2018-12-16 16:34:05 ERROR (SyncWorker_10) [homeassistant.components.light.yeelight] Failed to connect to bulb 192.168.87.56, Family Room Lamp: A socket error occurred when sending the command.
2018-12-16 16:34:07 ERROR (SyncWorker_0) [homeassistant.components.dyson] Unable to connect to device NetworkDevice(name=Office Hot+Cool,address=192.168.87.127,port=1883): [Errno 113] No route to host
2018-12-16 17:04:26 ERROR (MainThread) [homeassistant.components.websocket_api.http.connection.139781993195336] Error handling message: {'type': 'cloud/cloudhook/create', 'webhook_id': '8a261db22a97594f9ce23640f82dcd6987a09764650641358b103d8d9fdaf449', 'id': 18}
Traceback (most recent call last):
  File "/usr/src/app/homeassistant/components/websocket_api/decorators.py", line 16, in _handle_async_response
    await func(hass, connection, msg)
  File "/usr/src/app/homeassistant/components/cloud/http_api.py", line 292, in with_error_handling
    await handler(hass, connection, msg)
  File "/usr/src/app/homeassistant/components/cloud/http_api.py", line 355, in websocket_hook_create
    hook = await cloud.cloudhooks.async_create(msg['webhook_id'])
  File "/usr/src/app/homeassistant/components/cloud/cloudhooks.py", line 28, in async_create
    raise ValueError('Hook is already enabled for the cloud.')
ValueError: Hook is already enabled for the cloud.
